mplus_output/bi-35-MHAS_W2.out
Mplus VERSION 8.1 (Mac)
MUTHEN & MUTHEN
04/23/2020  10:57 PM

INPUT INSTRUCTIONS

  DATA:
  FILE = "bi-35-MHAS_W2.dat";

  VARIABLE:
  NAMES = mplusid UDAY UMON UYER UWR1 UWR2 UWR3 UFCO2 UFRE1 UWD UVSC;
   MISSING=.;
   CATEGORICAL ARE all; idvariable = mplusid;
  ANALYSIS:
  estimator = wlsmv; coverage=0;
  MODEL:
  g by UDAY * ;
   g by UMON * ;
   g by UYER * ;
   g by UWR1 * ;
   g by UWR2 * ;
   g by UWR3 * ;
   g by UFCO2 * ;
   g by UFRE1 * ;
   g by UWD * ;
   g by UVSC * ;
   s1 by UWR1 * ;
   s1 by UWR2 * ;
   s1 by UWR3 * ;
   s1 by UWD * ;
   g @ 1;
   s1 @ 1 ;
   g with s1 @ 0 ;

  OUTPUT:
  standardized; svalues;



*** WARNING
  Data set contains cases with missing on all variables.
  These cases were not included in the analysis.
  Number of cases with missing on all variables:  12
   1 WARNING(S) FOUND IN THE INPUT INSTRUCTIONS




SUMMARY OF ANALYSIS

Number of groups                                                 1
Number of observations                                       12411

Number of dependent variables                                   10
Number of independent variables                                  0
Number of continuous latent variables                            2

Observed dependent variables

  Binary and ordered categorical (ordinal)
   UDAY        UMON        UYER        UWR1        UWR2        UWR3
   UFCO2       UFRE1       UWD         UVSC

Continuous latent variables
   G           S1

Variables with special functions

  ID variable           MPLUSID

Estimator                                                    WLSMV
Maximum number of iterations                                  1000
Convergence criterion                                    0.500D-04
Maximum number of steepest descent iterations                   20
Maximum number of iterations for H1                           2000
Convergence criterion for H1                             0.100D-03
Parameterization                                             DELTA
Link                                                        PROBIT

Input data file(s)
  bi-35-MHAS_W2.dat

Input data format  FREE


SUMMARY OF DATA

     Number of missing data patterns            15


COVARIANCE COVERAGE OF DATA

Minimum covariance coverage value   0.000


     PROPORTION OF DATA PRESENT


           Covariance Coverage
              UDAY          UMON          UYER          UWR1          UWR2
              ________      ________      ________      ________      ________
 UDAY           1.000
 UMON           1.000         1.000
 UYER           1.000         1.000         1.000
 UWR1           0.971         0.971         0.971         0.971
 UWR2           0.971         0.971         0.971         0.971         0.971
 UWR3           0.971         0.971         0.971         0.971         0.971
 UFCO2          0.875         0.875         0.875         0.869         0.869
 UFRE1          0.864         0.864         0.864         0.859         0.859
 UWD            0.971         0.971         0.971         0.971         0.971
 UVSC           0.927         0.927         0.927         0.914         0.914


           Covariance Coverage
              UWR3          UFCO2         UFRE1         UWD           UVSC
              ________      ________      ________      ________      ________
 UWR3           0.971
 UFCO2          0.869         0.875
 UFRE1          0.859         0.864         0.864
 UWD            0.971         0.869         0.859         0.971
 UVSC           0.914         0.863         0.854         0.914         0.927


UNIVARIATE PROPORTIONS AND COUNTS FOR CATEGORICAL VARIABLES

    UDAY
      Category 1    0.275         3408.000
      Category 2    0.725         9000.000
    UMON
      Category 1    0.099         1226.000
      Category 2    0.901        11182.000
    UYER
      Category 1    0.181         2251.000
      Category 2    0.819        10157.000
    UWR1
      Category 1    0.041          495.000
      Category 2    0.070          840.000
      Category 3    0.177         2139.000
      Category 4    0.259         3122.000
      Category 5    0.237         2861.000
      Category 6    0.141         1695.000
      Category 7    0.060          722.000
      Category 8    0.013          155.000
      Category 9    0.002           22.000
    UWR2
      Category 1    0.017          206.000
      Category 2    0.020          244.000
      Category 3    0.064          770.000
      Category 4    0.159         1918.000
      Category 5    0.221         2658.000
      Category 6    0.224         2697.000
      Category 7    0.169         2037.000
      Category 8    0.090         1084.000
      Category 9    0.036          437.000
    UWR3
      Category 1    0.022          269.000
      Category 2    0.014          167.000
      Category 3    0.040          482.000
      Category 4    0.092         1108.000
      Category 5    0.149         1792.000
      Category 6    0.193         2324.000
      Category 7    0.212         2550.000
      Category 8    0.169         2033.000
      Category 9    0.110         1326.000
    UFCO2
      Category 1    0.080          868.000
      Category 2    0.178         1929.000
      Category 3    0.742         8060.000
    UFRE1
      Category 1    0.460         4932.000
      Category 2    0.292         3130.000
      Category 3    0.248         2662.000
    UWD
      Category 1    0.044          527.000
      Category 2    0.033          401.000
      Category 3    0.078          944.000
      Category 4    0.155         1867.000
      Category 5    0.209         2520.000
      Category 6    0.211         2548.000
      Category 7    0.150         1807.000
      Category 8    0.080          968.000
      Category 9    0.039          468.000
    UVSC
      Category 1    0.075          867.000
      Category 2    0.083          955.000
      Category 3    0.127         1456.000
      Category 4    0.146         1680.000
      Category 5    0.141         1619.000
      Category 6    0.117         1351.000
      Category 7    0.092         1063.000
      Category 8    0.071          815.000
      Category 9    0.062          718.000
      Category 10    0.086          984.000



THE MODEL ESTIMATION TERMINATED NORMALLY



MODEL FIT INFORMATION

Number of Free Parameters                       62

Chi-Square Test of Model Fit

          Value                           3035.222*
          Degrees of Freedom                    31
          P-Value                           0.0000

*   The chi-square value for MLM, MLMV, MLR, ULSMV, WLSM and WLSMV cannot be used
    for chi-square difference testing in the regular way.  MLM, MLR and WLSM
    chi-square difference testing is described on the Mplus website.  MLMV, WLSMV,
    and ULSMV difference testing is done using the DIFFTEST option.

RMSEA (Root Mean Square Error Of Approximation)

          Estimate                           0.088
          90 Percent C.I.                    0.086  0.091
          Probability RMSEA <= .05           0.000

CFI/TLI

          CFI                                0.974
          TLI                                0.962

Chi-Square Test of Model Fit for the Baseline Model

          Value                         115394.639
          Degrees of Freedom                    45
          P-Value                           0.0000

SRMR (Standardized Root Mean Square Residual)

          Value                              0.057

Optimum Function Value for Weighted Least-Squares Estimator

          Value                     0.85273792D-01



MODEL RESULTS

                                                    Two-Tailed
                    Estimate       S.E.  Est./S.E.    P-Value

 G        BY
    UDAY               0.623      0.010     63.851      0.000
    UMON               0.820      0.011     72.475      0.000
    UYER               0.858      0.008    106.214      0.000
    UWR1               0.559      0.008     73.189      0.000
    UWR2               0.568      0.008     74.257      0.000
